client/output.csv
B, B, 0, 0
B, S, 0, 0
B, B, 0, 0
B, S, 0, 0
B, B, 0, 0
B, S, 0, 0
B, B, 0, 0
B, S, 0, 0
B, B, 0, 0
B, S, 0, 0
B, B, 0, 0
B, S, 0, 0
B, B, 0, 0
B, S, 0, 0
B, B, 0, 0
B, S, 0, 0
B, B, 0, 0
B, S, 0, 0
B, B, 0, 0
B, S, 0, 0
B, B, 0, 0
B, S, 0, 0
B, B, 0, 0
B, S, 0, 0
B, B, 0, 0
B, S, 0, 0
B, B, 0, 0
B, S, 0, 0
B, B, 0, 0
B, S, 0, 0
B, B, 0, 0
B, S, 0, 0
